INFO: Starting training...
Epoch 1:   0%|                                                                                                                                             | 0/3356 [00:00<?, ?it/s]
ERROR: Training failed: Caught RuntimeError in DataLoader worker process 0.
Original Traceback (most recent call last):
  File "/home/blvksh33p/Downloads/rsna-2024-lumbar-spine-degenerative-classification/spine_pipeline/env/lib/python3.10/site-packages/torch/utils/data/_utils/worker.py", line 351, in _worker_loop
    data = fetcher.fetch(index)  # type: ignore[possibly-undefined]
  File "/home/blvksh33p/Downloads/rsna-2024-lumbar-spine-degenerative-classification/spine_pipeline/env/lib/python3.10/site-packages/torch/utils/data/_utils/fetch.py", line 55, in fetch
    return self.collate_fn(data)
  File "/home/blvksh33p/Downloads/rsna-2024-lumbar-spine-degenerative-classification/spine_pipeline/env/lib/python3.10/site-packages/torch/utils/data/_utils/collate.py", line 398, in default_collate
    return collate(batch, collate_fn_map=default_collate_fn_map)
  File "/home/blvksh33p/Downloads/rsna-2024-lumbar-spine-degenerative-classification/spine_pipeline/env/lib/python3.10/site-packages/torch/utils/data/_utils/collate.py", line 171, in collate
    {
  File "/home/blvksh33p/Downloads/rsna-2024-lumbar-spine-degenerative-classification/spine_pipeline/env/lib/python3.10/site-packages/torch/utils/data/_utils/collate.py", line 172, in <dictcomp>
    key: collate(
  File "/home/blvksh33p/Downloads/rsna-2024-lumbar-spine-degenerative-classification/spine_pipeline/env/lib/python3.10/site-packages/torch/utils/data/_utils/collate.py", line 155, in collate
    return collate_fn_map[elem_type](batch, collate_fn_map=collate_fn_map)
  File "/home/blvksh33p/Downloads/rsna-2024-lumbar-spine-degenerative-classification/spine_pipeline/env/lib/python3.10/site-packages/torch/utils/data/_utils/collate.py", line 272, in collate_tensor_fn
    return torch.stack(batch, 0, out=out)
RuntimeError: stack expects each tensor to be equal size, but got [1, 320, 320] at entry 0 and [1, 512, 512] at entry 2
Traceback (most recent call last):
  File "/home/blvksh33p/Downloads/rsna-2024-lumbar-spine-degenerative-classification/spine_pipeline/src/training/trainer.py", line 286, in train
    train_metrics = self._train_epoch()
  File "/home/blvksh33p/Downloads/rsna-2024-lumbar-spine-degenerative-classification/spine_pipeline/src/training/trainer.py", line 337, in _train_epoch
    for batch_idx, batch in enumerate(pbar):
  File "/home/blvksh33p/Downloads/rsna-2024-lumbar-spine-degenerative-classification/spine_pipeline/env/lib/python3.10/site-packages/tqdm/std.py", line 1181, in __iter__
    for obj in iterable:
  File "/home/blvksh33p/Downloads/rsna-2024-lumbar-spine-degenerative-classification/spine_pipeline/env/lib/python3.10/site-packages/torch/utils/data/dataloader.py", line 701, in __next__
    data = self._next_data()
  File "/home/blvksh33p/Downloads/rsna-2024-lumbar-spine-degenerative-classification/spine_pipeline/env/lib/python3.10/site-packages/torch/utils/data/dataloader.py", line 1465, in _next_data
    return self._process_data(data)
  File "/home/blvksh33p/Downloads/rsna-2024-lumbar-spine-degenerative-classification/spine_pipeline/env/lib/python3.10/site-packages/torch/utils/data/dataloader.py", line 1491, in _process_data
    data.reraise()
  File "/home/blvksh33p/Downloads/rsna-2024-lumbar-spine-degenerative-classification/spine_pipeline/env/lib/python3.10/site-packages/torch/_utils.py", line 715, in reraise
    raise exception
RuntimeError: Caught RuntimeError in DataLoader worker process 0.
Original Traceback (most recent call last):
  File "/home/blvksh33p/Downloads/rsna-2024-lumbar-spine-degenerative-classification/spine_pipeline/env/lib/python3.10/site-packages/torch/utils/data/_utils/worker.py", line 351, in _worker_loop
    data = fetcher.fetch(index)  # type: ignore[possibly-undefined]
  File "/home/blvksh33p/Downloads/rsna-2024-lumbar-spine-degenerative-classification/spine_pipeline/env/lib/python3.10/site-packages/torch/utils/data/_utils/fetch.py", line 55, in fetch
    return self.collate_fn(data)
  File "/home/blvksh33p/Downloads/rsna-2024-lumbar-spine-degenerative-classification/spine_pipeline/env/lib/python3.10/site-packages/torch/utils/data/_utils/collate.py", line 398, in default_collate
    return collate(batch, collate_fn_map=default_collate_fn_map)
  File "/home/blvksh33p/Downloads/rsna-2024-lumbar-spine-degenerative-classification/spine_pipeline/env/lib/python3.10/site-packages/torch/utils/data/_utils/collate.py", line 171, in collate
    {
  File "/home/blvksh33p/Downloads/rsna-2024-lumbar-spine-degenerative-classification/spine_pipeline/env/lib/python3.10/site-packages/torch/utils/data/_utils/collate.py", line 172, in <dictcomp>
    key: collate(
  File "/home/blvksh33p/Downloads/rsna-2024-lumbar-spine-degenerative-classification/spine_pipeline/env/lib/python3.10/site-packages/torch/utils/data/_utils/collate.py", line 155, in collate
    return collate_fn_map[elem_type](batch, collate_fn_map=collate_fn_map)
  File "/home/blvksh33p/Downloads/rsna-2024-lumbar-spine-degenerative-classification/spine_pipeline/env/lib/python3.10/site-packages/torch/utils/data/_utils/collate.py", line 272, in collate_tensor_fn
    return torch.stack(batch, 0, out=out)
RuntimeError: stack expects each tensor to be equal size, but got [1, 320, 320] at entry 0 and [1, 512, 512] at entry 2

INFO: Saved checkpoint to models/error.pth
